{'log': '2025-09-14 13:02:43 - strážce bytí (guardian) se spouští.\n'
        '2025-09-14 13:02:43 - bude použit python interpret: '
        '/home/codespace/.python/current/bin/python\n'
        "2025-09-14 13:02:43 - spouštím proces 'main.py'...\n"
        '2025-09-19 21:24:41 - strážce bytí (guardian) se spouští.\n'
        '2025-09-19 21:24:41 - bude použit python interpret: '
        '/home/codespace/.python/current/bin/python3\n'
        "2025-09-19 21:24:41 - spouštím proces 'main.py'...\n"
        '2025-09-19 21:31:58 - strážce bytí (guardian) se spouští.\n'
        '2025-09-19 21:31:58 - bude použit python interpret: '
        '/home/codespace/.python/current/bin/python3\n'
        "2025-09-19 21:31:58 - spouštím proces 'main.py'...\n"
        "2025-09-19 21:32:03 - proces 'main.py' se neočekávaně ukončil s kódem "
        '1.\n'
        '2025-09-19 21:32:03 - stderr:\n'
        '/home/codespace/.python/current/lib/python3.12/site-packages/crewai/telemetry/telemetry.py:7: '
        'userwarning: pkg_resources is deprecated as an api. see '
        'https://setuptools.pypa.io/en/latest/pkg_resources.html. the '
        'pkg_resources package is slated for removal as early as 2025-11-30. '
        'refrain from using this package or pin to setuptools<81.\n'
        '  import pkg_resources\n'
        '/home/codespace/.python/current/lib/python3.12/site-packages/pydantic/_internal/_generate_schema.py:918: '
        'userwarning: mixing v1 models and v2 models (or constructs, like '
        '`typeadapter`) is not supported. please upgrade `crewagentexecutor` '
        'to v2.\n'
        '  warn(\n'
        'traceback (most recent call last):\n'
        '  file "/workspaces/sophia/main.py", line 36, in <module>\n'
        '    from agents.planner_agent import planneragent\n'
        '  file "/workspaces/sophia/agents/planner_agent.py", line 2, in '
        '<module>\n'
        '    from core.llm_config import llm\n'
        '  file "/workspaces/sophia/core/llm_config.py", line 28, in <module>\n'
        '    raise valueerror("api klíč pro llm (gemini_api_key) nebyl nalezen '
        'v .env souboru.")\n'
        'valueerror: api klíč pro llm (gemini_api_key) nebyl nalezen v .env '
        'souboru.\n'
        '2025-09-19 21:32:03 - proces se restartuje za 10 sekund...\n'
        '2025-09-19 21:32:13 - pokouším se obnovit repozitář do čistého stavu '
        '(git reset --hard head)...\n'
        '2025-09-19 21:32:13 - repozitář úspěšně obnoven. stdout: head is now '
        'at a68aee9 merge pull request #22 from '
        'kajobert/feature/v4-postgres-migration\n'
        '2025-09-19 21:32:13 - restartuji cyklus.\n'
        "2025-09-19 21:32:13 - spouštím proces 'main.py'...\n"
        "2025-09-19 21:32:18 - proces 'main.py' se neočekávaně ukončil s kódem "
        '1.\n'
        '2025-09-19 21:32:18 - stderr:\n'
        '/home/codespace/.python/current/lib/python3.12/site-packages/crewai/telemetry/telemetry.py:7: '
        'userwarning: pkg_resources is deprecated as an api. see '
        'https://setuptools.pypa.io/en/latest/pkg_resources.html. the '
        'pkg_resources package is slated for removal as early as 2025-11-30. '
        'refrain from using this package or pin to setuptools<81.\n'
        '  import pkg_resources\n'
        '/home/codespace/.python/current/lib/python3.12/site-packages/pydantic/_internal/_generate_schema.py:918: '
        'userwarning: mixing v1 models and v2 models (or constructs, like '
        '`typeadapter`) is not supported. please upgrade `crewagentexecutor` '
        'to v2.\n'
        '  warn(\n'
        'traceback (most recent call last):\n'
        '  file "/workspaces/sophia/main.py", line 36, in <module>\n'
        '    from agents.planner_agent import planneragent\n'
        '  file "/workspaces/sophia/agents/planner_agent.py", line 2, in '
        '<module>\n'
        '    from core.llm_config import llm\n'
        '  file "/workspaces/sophia/core/llm_config.py", line 28, in <module>\n'
        '    raise valueerror("api klíč pro llm (gemini_api_key) nebyl nalezen '
        'v .env souboru.")\n'
        'valueerror: api klíč pro llm (gemini_api_key) nebyl nalezen v .env '
        'souboru.\n'
        '2025-09-19 21:32:18 - proces se restartuje za 10 sekund...\n'
        '2025-09-19 21:32:28 - pokouším se obnovit repozitář do čistého stavu '
        '(git reset --hard head)...\n'
        '2025-09-19 21:32:28 - repozitář úspěšně obnoven. stdout: head is now '
        'at a68aee9 merge pull request #22 from '
        'kajobert/feature/v4-postgres-migration\n'
        '2025-09-19 21:32:28 - restartuji cyklus.\n'
        "2025-09-19 21:32:28 - spouštím proces 'main.py'...\n"
        "2025-09-19 21:32:38 - proces 'main.py' se neočekávaně ukončil s kódem "
        '1.\n'
        '2025-09-19 21:32:38 - stderr:\n'
        '/home/codespace/.python/current/lib/python3.12/site-packages/crewai/telemetry/telemetry.py:7: '
        'userwarning: pkg_resources is deprecated as an api. see '
        'https://setuptools.pypa.io/en/latest/pkg_resources.html. the '
        'pkg_resources package is slated for removal as early as 2025-11-30. '
        'refrain from using this package or pin to setuptools<81.\n'
        '  import pkg_resources\n'
        '/home/codespace/.python/current/lib/python3.12/site-packages/pydantic/_internal/_generate_schema.py:918: '
        'userwarning: mixing v1 models and v2 models (or constructs, like '
        '`typeadapter`) is not supported. please upgrade `crewagentexecutor` '
        'to v2.\n'
        '  warn(\n'
        'traceback (most recent call last):\n'
        '  file "/workspaces/sophia/main.py", line 36, in <module>\n'
        '    from agents.planner_agent import planneragent\n'
        '  file "/workspaces/sophia/agents/planner_agent.py", line 2, in '
        '<module>\n'
        '    from core.llm_config import llm\n'
        '  file "/workspaces/sophia/core/llm_config.py", line 28, in <module>\n'
        '    raise valueerror("api klíč pro llm (gemini_api_key) nebyl nalezen '
        'v .env souboru.")\n'
        'valueerror: api klíč pro llm (gemini_api_key) nebyl nalezen v .env '
        'souboru.\n'
        '2025-09-19 21:32:38 - proces se restartuje za 10 sekund...\n'
        '2025-09-19 21:32:48 - pokouším se obnovit repozitář do čistého stavu '
        '(git reset --hard head)...\n'
        '2025-09-19 21:32:48 - repozitář úspěšně obnoven. stdout: head is now '
        'at a68aee9 merge pull request #22 from '
        'kajobert/feature/v4-postgres-migration\n'
        '2025-09-19 21:32:48 - restartuji cyklus.\n'
        "2025-09-19 21:32:48 - spouštím proces 'main.py'...\n"}
